<?xml version="1.0" encoding="utf-8"?>
<!-- This URDF was automatically created by SolidWorks to URDF Exporter! Originally created by Stephen Brawner (brawner@gmail.com) 
     Commit Version: 1.6.0-4-g7f85cfe  Build Version: 1.6.7995.38578
     For more information, please see http://wiki.ros.org/sw_urdf_exporter -->
<robot
  name="robot_urdf4">
  <link
    name="base_link">
    <inertial>
      <origin
        xyz="-0.12216 -0.00092925 -0.066105"
        rpy="0 0 0" />
      <mass
        value="28.363" />
      <inertia
        ixx="1.2348"
        ixy="-0.0062151"
        ixz="0.061302"
        iyy="0.87584"
        iyz="0.00059839"
        izz="1.6389" />
    </inertial>
    <visual>
      <origin
        xyz="0 0 0"
        rpy="0 0 0" />
      <geometry>
        <mesh
          filename="package://robot_urdf4/meshes/base_link.STL" />
      </geometry>
      <material
        name="">
        <color
          rgba="0.79216 0.81961 0.93333 1" />
      </material>
    </visual>
    <collision>
      <origin
        xyz="0 0 0"
        rpy="0 0 0" />
      <geometry>
        <mesh
          filename="package://robot_urdf4/meshes/base_link.STL" />
      </geometry>
    </collision>
  </link>
  <link
    name="banhtrai">
    <inertial>
      <origin
        xyz="-4.44079217842841E-10 -0.0145723974412093 3.05568181868665E-10"
        rpy="0 0 0" />
      <mass
        value="0.365884677160109" />
      <inertia
        ixx="0.00072840393872265"
        ixy="-1.28300005559611E-12"
        ixz="2.98288035903E-12"
        iyy="0.00131510257761303"
        iyz="3.63718745273062E-12"
        izz="0.000728403935773149" />
    </inertial>
    <visual>
      <origin
        xyz="0 0 0"
        rpy="0 0 0" />
      <geometry>
        <mesh
          filename="package://robot_urdf4/meshes/banhtrai.STL" />
      </geometry>
      <material
        name="">
        <color
          rgba="1 0.807843137254902 0.498039215686275 1" />
      </material>
    </visual>
    <collision>
      <origin
        xyz="0 0 0"
        rpy="0 0 0" />
      <geometry>
        <mesh
          filename="package://robot_urdf4/meshes/banhtrai.STL" />
      </geometry>
    </collision>
  </link>
  <joint
    name="khoptrai"
    type="continuous">
    <origin
      xyz="-0.27765 0.36108 -0.22397"
      rpy="0 0 0" />
    <parent
      link="base_link" />
    <child
      link="banhtrai" />
    <axis
      xyz="0 1 0" />
  </joint>
  <link
    name="banhphai">
    <inertial>
      <origin
        xyz="9.46449307814845E-11 0.0145723975121261 -3.16541265421577E-10"
        rpy="0 0 0" />
      <mass
        value="0.365884678332014" />
      <inertia
        ixx="0.000728403937436423"
        ixy="1.89847387657964E-12"
        ixz="-1.70465896340821E-12"
        iyy="0.00131510258079819"
        iyz="1.8909251696871E-12"
        izz="0.000728403941514376" />
    </inertial>
    <visual>
      <origin
        xyz="0 0 0"
        rpy="0 0 0" />
      <geometry>
        <mesh
          filename="package://robot_urdf4/meshes/banhphai.STL" />
      </geometry>
      <material
        name="">
        <color
          rgba="1 0.807843137254902 0.498039215686275 1" />
      </material>
    </visual>
    <collision>
      <origin
        xyz="0 0 0"
        rpy="0 0 0" />
      <geometry>
        <mesh
          filename="package://robot_urdf4/meshes/banhphai.STL" />
      </geometry>
    </collision>
  </link>
  <joint
    name="khopphai"
    type="continuous">
    <origin
      xyz="-0.27765 -0.36108 -0.22397"
      rpy="0 0 0" />
    <parent
      link="base_link" />
    <child
      link="banhphai" />
    <axis
      xyz="0 1 0" />
  </joint>
</robot>